Workbook

Sheet TEAM
A1: Position | B1: Player | C1: Team | D1: Price (m) | E1: Expected Points
A2: =IFERROR(INDEX(TEAM_BUILDER!$A$6:$A$201,MATCH(1,INDEX((TEAM_BUILDER!$G$6:$G$201=1)*(COUNTIF($B$1:B1,TEAM_BUILDER!$C$6:$C$201)=0),0),0)),"") -> GK | B2: =IFERROR(INDEX(TEAM_BUILDER!$C$6:$C$201,MATCH(ROWS($B$2:B2),TEAM_BUILDER!$I$6:$I$201,0)),"") -> Konstantinos Tzolakis | C2: =IFERROR(INDEX(TEAM_BUILDER!$D$6:$D$201,MATCH($B2,TEAM_BUILDER!$C$6:$C$201,0)),"") -> HUL | D2: =IFERROR(INDEX(TEAM_BUILDER!$E$6:$E$201,MATCH($B2,TEAM_BUILDER!$C$6:$C$201,0)),"") -> 4.6 | E2: =IFERROR(INDEX(TEAM_BUILDER!$H$6:$H$201,MATCH($B2,TEAM_BUILDER!$C$6:$C$201,0)),"") -> 8.4
A3: =IFERROR(INDEX(TEAM_BUILDER!$A$6:$A$201,MATCH(1,INDEX((TEAM_BUILDER!$G$6:$G$201=1)*(COUNTIF($B$1:B2,TEAM_BUILDER!$C$6:$C$201)=0),0),0)),"") -> GK | B3: =IFERROR(INDEX(TEAM_BUILDER!$C$6:$C$201,MATCH(ROWS($B$2:B3),TEAM_BUILDER!$I$6:$I$201,0)),"") -> David Raya Martín | C3: =IFERROR(INDEX(TEAM_BUILDER!$D$6:$D$201,MATCH($B3,TEAM_BUILDER!$C$6:$C$201,0)),"") -> ARS | D3: =IFERROR(INDEX(TEAM_BUILDER!$E$6:$E$201,MATCH($B3,TEAM_BUILDER!$C$6:$C$201,0)),"") -> 6 | E3: =IFERROR(INDEX(TEAM_BUILDER!$H$6:$H$201,MATCH($B3,TEAM_BUILDER!$C$6:$C$201,0)),"") -> 6.1779862
A4: =IFERROR(INDEX(TEAM_BUILDER!$A$6:$A$201,MATCH(1,INDEX((TEAM_BUILDER!$G$6:$G$201=1)*(COUNTIF($B$1:B3,TEAM_BUILDER!$C$6:$C$201)=0),0),0)),"") -> DEF | B4: =IFERROR(INDEX(TEAM_BUILDER!$C$6:$C$201,MATCH(ROWS($B$2:B4),TEAM_BUILDER!$I$6:$I$201,0)),"") -> John Egan | C4: =IFERROR(INDEX(TEAM_BUILDER!$D$6:$D$201,MATCH($B4,TEAM_BUILDER!$C$6:$C$201,0)),"") -> HUL | D4: =IFERROR(INDEX(TEAM_BUILDER!$E$6:$E$201,MATCH($B4,TEAM_BUILDER!$C$6:$C$201,0)),"") -> 4.1 | E4: =IFERROR(INDEX(TEAM_BUILDER!$H$6:$H$201,MATCH($B4,TEAM_BUILDER!$C$6:$C$201,0)),"") -> 10.502855
A5: =IFERROR(INDEX(TEAM_BUILDER!$A$6:$A$201,MATCH(1,INDEX((TEAM_BUILDER!$G$6:$G$201=1)*(COUNTIF($B$1:B4,TEAM_BUILDER!$C$6:$C$201)=0),0),0)),"") -> DEF | B5: =IFERROR(INDEX(TEAM_BUILDER!$C$6:$C$201,MATCH(ROWS($B$2:B5),TEAM_BUILDER!$I$6:$I$201,0)),"") -> Semi Ajayi | C5: =IFERROR(INDEX(TEAM_BUILDER!$D$6:$D$201,MATCH($B5,TEAM_BUILDER!$C$6:$C$201,0)),"") -> HUL | D5: =IFERROR(INDEX(TEAM_BUILDER!$E$6:$E$201,MATCH($B5,TEAM_BUILDER!$C$6:$C$201,0)),"") -> 4.1 | E5: =IFERROR(INDEX(TEAM_BUILDER!$H$6:$H$201,MATCH($B5,TEAM_BUILDER!$C$6:$C$201,0)),"") -> 10.364444
A6: =IFERROR(INDEX(TEAM_BUILDER!$A$6:$A$201,MATCH(1,INDEX((TEAM_BUILDER!$G$6:$G$201=1)*(COUNTIF($B$1:B5,TEAM_BUILDER!$C$6:$C$201)=0),0),0)),"") -> DEF | B6: =IFERROR(INDEX(TEAM_BUILDER!$C$6:$C$201,MATCH(ROWS($B$2:B6),TEAM_BUILDER!$I$6:$I$201,0)),"") -> Gabriel dos Santos Magalhães | C6: =IFERROR(INDEX(TEAM_BUILDER!$D$6:$D$201,MATCH($B6,TEAM_BUILDER!$C$6:$C$201,0)),"") -> ARS | D6: =IFERROR(INDEX(TEAM_BUILDER!$E$6:$E$201,MATCH($B6,TEAM_BUILDER!$C$6:$C$201,0)),"") -> 8 | E6: =IFERROR(INDEX(TEAM_BUILDER!$H$6:$H$201,MATCH($B6,TEAM_BUILDER!$C$6:$C$201,0)),"") -> 8.1528293 | H6: =IF(G6=1,COUNTIF($G$6:G6,1),"")
A7: =IFERROR(INDEX(TEAM_BUILDER!$A$6:$A$201,MATCH(1,INDEX((TEAM_BUILDER!$G$6:$G$201=1)*(COUNTIF($B$1:B6,TEAM_BUILDER!$C$6:$C$201)=0),0),0)),"") -> DEF | B7: =IFERROR(INDEX(TEAM_BUILDER!$C$6:$C$201,MATCH(ROWS($B$2:B7),TEAM_BUILDER!$I$6:$I$201,0)),"") -> Jayden Bogle | C7: =IFERROR(INDEX(TEAM_BUILDER!$D$6:$D$201,MATCH($B7,TEAM_BUILDER!$C$6:$C$201,0)),"") -> LEE | D7: =IFERROR(INDEX(TEAM_BUILDER!$E$6:$E$201,MATCH($B7,TEAM_BUILDER!$C$6:$C$201,0)),"") -> 4.5 | E7: =IFERROR(INDEX(TEAM_BUILDER!$H$6:$H$201,MATCH($B7,TEAM_BUILDER!$C$6:$C$201,0)),"") -> 8.1476383
A8: =IFERROR(INDEX(TEAM_BUILDER!$A$6:$A$201,MATCH(1,INDEX((TEAM_BUILDER!$G$6:$G$201=1)*(COUNTIF($B$1:B7,TEAM_BUILDER!$C$6:$C$201)=0),0),0)),"") -> DEF | B8: =IFERROR(INDEX(TEAM_BUILDER!$C$6:$C$201,MATCH(ROWS($B$2:B8),TEAM_BUILDER!$I$6:$I$201,0)),"") -> Riccardo Calafiori | C8: =IFERROR(INDEX(TEAM_BUILDER!$D$6:$D$201,MATCH($B8,TEAM_BUILDER!$C$6:$C$201,0)),"") -> ARS | D8: =IFERROR(INDEX(TEAM_BUILDER!$E$6:$E$201,MATCH($B8,TEAM_BUILDER!$C$6:$C$201,0)),"") -> 5.7 | E8: =IFERROR(INDEX(TEAM_BUILDER!$H$6:$H$201,MATCH($B8,TEAM_BUILDER!$C$6:$C$201,0)),"") -> 8.1388646
A9: =IFERROR(INDEX(TEAM_BUILDER!$A$6:$A$201,MATCH(1,INDEX((TEAM_BUILDER!$G$6:$G$201=1)*(COUNTIF($B$1:B8,TEAM_BUILDER!$C$6:$C$201)=0),0),0)),"") -> MID | B9: =IFERROR(INDEX(TEAM_BUILDER!$C$6:$C$201,MATCH(ROWS($B$2:B9),TEAM_BUILDER!$I$6:$I$201,0)),"") -> Bryan Mbeumo | C9: =IFERROR(INDEX(TEAM_BUILDER!$D$6:$D$201,MATCH($B9,TEAM_BUILDER!$C$6:$C$201,0)),"") -> MUN | D9: =IFERROR(INDEX(TEAM_BUILDER!$E$6:$E$201,MATCH($B9,TEAM_BUILDER!$C$6:$C$201,0)),"") -> 7.9 | E9: =IFERROR(INDEX(TEAM_BUILDER!$H$6:$H$201,MATCH($B9,TEAM_BUILDER!$C$6:$C$201,0)),"") -> 7.787795
A10: =IFERROR(INDEX(TEAM_BUILDER!$A$6:$A$201,MATCH(1,INDEX((TEAM_BUILDER!$G$6:$G$201=1)*(COUNTIF($B$1:B9,TEAM_BUILDER!$C$6:$C$201)=0),0),0)),"") -> MID | B10: =IFERROR(INDEX(TEAM_BUILDER!$C$6:$C$201,MATCH(ROWS($B$2:B10),TEAM_BUILDER!$I$6:$I$201,0)),"") -> Phil Foden | C10: =IFERROR(INDEX(TEAM_BUILDER!$D$6:$D$201,MATCH($B10,TEAM_BUILDER!$C$6:$C$201,0)),"") -> MCI | D10: =IFERROR(INDEX(TEAM_BUILDER!$E$6:$E$201,MATCH($B10,TEAM_BUILDER!$C$6:$C$201,0)),"") -> 7 | E10: =IFERROR(INDEX(TEAM_BUILDER!$H$6:$H$201,MATCH($B10,TEAM_BUILDER!$C$6:$C$201,0)),"") -> 7.6213819
A11: =IFERROR(INDEX(TEAM_BUILDER!$A$6:$A$201,MATCH(1,INDEX((TEAM_BUILDER!$G$6:$G$201=1)*(COUNTIF($B$1:B10,TEAM_BUILDER!$C$6:$C$201)=0),0),0)),"") -> MID | B11: =IFERROR(INDEX(TEAM_BUILDER!$C$6:$C$201,MATCH(ROWS($B$2:B11),TEAM_BUILDER!$I$6:$I$201,0)),"") -> Dango Ouattara | C11: =IFERROR(INDEX(TEAM_BUILDER!$D$6:$D$201,MATCH($B11,TEAM_BUILDER!$C$6:$C$201,0)),"") -> BRE | D11: =IFERROR(INDEX(TEAM_BUILDER!$E$6:$E$201,MATCH($B11,TEAM_BUILDER!$C$6:$C$201,0)),"") -> 6.4 | E11: =IFERROR(INDEX(TEAM_BUILDER!$H$6:$H$201,MATCH($B11,TEAM_BUILDER!$C$6:$C$201,0)),"") -> 7.4311304
A12: =IFERROR(INDEX(TEAM_BUILDER!$A$6:$A$201,MATCH(1,INDEX((TEAM_BUILDER!$G$6:$G$201=1)*(COUNTIF($B$1:B11,TEAM_BUILDER!$C$6:$C$201)=0),0),0)),"") -> MID | B12: =IFERROR(INDEX(TEAM_BUILDER!$C$6:$C$201,MATCH(ROWS($B$2:B12),TEAM_BUILDER!$I$6:$I$201,0)),"") -> Rayan Cherki | C12: =IFERROR(INDEX(TEAM_BUILDER!$D$6:$D$201,MATCH($B12,TEAM_BUILDER!$C$6:$C$201,0)),"") -> MCI | D12: =IFERROR(INDEX(TEAM_BUILDER!$E$6:$E$201,MATCH($B12,TEAM_BUILDER!$C$6:$C$201,0)),"") -> 7.8 | E12: =IFERROR(INDEX(TEAM_BUILDER!$H$6:$H$201,MATCH($B12,TEAM_BUILDER!$C$6:$C$201,0)),"") -> 7.2204286
A13: =IFERROR(INDEX(TEAM_BUILDER!$A$6:$A$201,MATCH(1,INDEX((TEAM_BUILDER!$G$6:$G$201=1)*(COUNTIF($B$1:B12,TEAM_BUILDER!$C$6:$C$201)=0),0),0)),"") -> MID | B13: =IFERROR(INDEX(TEAM_BUILDER!$C$6:$C$201,MATCH(ROWS($B$2:B13),TEAM_BUILDER!$I$6:$I$201,0)),"") -> Andrey Nascimento dos Santos | C13: =IFERROR(INDEX(TEAM_BUILDER!$D$6:$D$201,MATCH($B13,TEAM_BUILDER!$C$6:$C$201,0)),"") -> MUN | D13: =IFERROR(INDEX(TEAM_BUILDER!$E$6:$E$201,MATCH($B13,TEAM_BUILDER!$C$6:$C$201,0)),"") -> 4.9 | E13: =IFERROR(INDEX(TEAM_BUILDER!$H$6:$H$201,MATCH($B13,TEAM_BUILDER!$C$6:$C$201,0)),"") -> 7.0275502
A14: =IFERROR(INDEX(TEAM_BUILDER!$A$6:$A$201,MATCH(1,INDEX((TEAM_BUILDER!$G$6:$G$201=1)*(COUNTIF($B$1:B13,TEAM_BUILDER!$C$6:$C$201)=0),0),0)),"") -> FWD | B14: =IFERROR(INDEX(TEAM_BUILDER!$C$6:$C$201,MATCH(ROWS($B$2:B14),TEAM_BUILDER!$I$6:$I$201,0)),"") -> Erling Haaland | C14: =IFERROR(INDEX(TEAM_BUILDER!$D$6:$D$201,MATCH($B14,TEAM_BUILDER!$C$6:$C$201,0)),"") -> MCI | D14: =IFERROR(INDEX(TEAM_BUILDER!$E$6:$E$201,MATCH($B14,TEAM_BUILDER!$C$6:$C$201,0)),"") -> 15.5 | E14: =IFERROR(INDEX(TEAM_BUILDER!$H$6:$H$201,MATCH($B14,TEAM_BUILDER!$C$6:$C$201,0)),"") -> 7.7831264
A15: =IFERROR(INDEX(TEAM_BUILDER!$A$6:$A$201,MATCH(1,INDEX((TEAM_BUILDER!$G$6:$G$201=1)*(COUNTIF($B$1:B14,TEAM_BUILDER!$C$6:$C$201)=0),0),0)),"") -> FWD | B15: =IFERROR(INDEX(TEAM_BUILDER!$C$6:$C$201,MATCH(ROWS($B$2:B15),TEAM_BUILDER!$I$6:$I$201,0)),"") -> Igor Thiago Nascimento Rodrigues | C15: =IFERROR(INDEX(TEAM_BUILDER!$D$6:$D$201,MATCH($B15,TEAM_BUILDER!$C$6:$C$201,0)),"") -> BRE | D15: =IFERROR(INDEX(TEAM_BUILDER!$E$6:$E$201,MATCH($B15,TEAM_BUILDER!$C$6:$C$201,0)),"") -> 7.9 | E15: =IFERROR(INDEX(TEAM_BUILDER!$H$6:$H$201,MATCH($B15,TEAM_BUILDER!$C$6:$C$201,0)),"") -> 6.688367
A16: =IFERROR(INDEX(TEAM_BUILDER!$A$6:$A$201,MATCH(1,INDEX((TEAM_BUILDER!$G$6:$G$201=1)*(COUNTIF($B$1:B15,TEAM_BUILDER!$C$6:$C$201)=0),0),0)),"") -> FWD | B16: =IFERROR(INDEX(TEAM_BUILDER!$C$6:$C$201,MATCH(ROWS($B$2:B16),TEAM_BUILDER!$I$6:$I$201,0)),"") -> Thierno Barry | C16: =IFERROR(INDEX(TEAM_BUILDER!$D$6:$D$201,MATCH($B16,TEAM_BUILDER!$C$6:$C$201,0)),"") -> EVE | D16: =IFERROR(INDEX(TEAM_BUILDER!$E$6:$E$201,MATCH($B16,TEAM_BUILDER!$C$6:$C$201,0)),"") -> 5.6 | E16: =IFERROR(INDEX(TEAM_BUILDER!$H$6:$H$201,MATCH($B16,TEAM_BUILDER!$C$6:$C$201,0)),"") -> 6.2822815
D18: =SUM(D2:D16) -> 100

Sheet TEAM_BUILDER
A1: FPL TEAM BUILDER
N2: Club | O2: Players
A3: Budget | B3: 100 | N3: ARS | O3: =SUMPRODUCT((D9:D598=N3)*G9:G598) -> 3 | P3: =IF(O3>3,"TOO MANY","OK") -> OK
A4: Squad Cost | N4: AVL | O4: =SUMPRODUCT((D9:D598=N4)*G9:G598) -> 0 | P4: =IF(O4>3,"TOO MANY","OK") -> OK
A5: Remaining Budget | L5: Metric | M5: Value | N5: BHA | O5: =SUMPRODUCT((D9:D598=N5)*G9:G598) -> 0 | P5: =IF(O5>3,"TOO MANY","OK") -> OK
A6: Squad Players | L6: Squad Cost | M6: =SUMPRODUCT($E$9:$E$160,$G$9:$G$160) -> 100 | N6: BOU | O6: =SUMPRODUCT((D9:D598=N6)*G9:G598) -> 0 | P6: =IF(O6>3,"TOO MANY","OK") -> OK
L7: Expected Points | M7: =SUMPRODUCT($H$9:$H$160,$G$9:$G$160) -> 117.72668 | N7: BRE | O7: =SUMPRODUCT((D9:D598=N7)*G9:G598) -> 2 | P7: =IF(O7>3,"TOO MANY","OK") -> OK
A8: Position | B8: rank | C8: Player | D8: Team | E8: Price | F8: Model Score | G8: selected | H8: Expected Points | I8: Selection Order | J8: Eligible | L8: Remaining Budget | M8: =$B$3-$M$6 -> 0 | N8: COV | O8: =SUMPRODUCT((D9:D598=N8)*G9:G598) -> 0 | P8: =IF(O8>3,"TOO MANY","OK") -> OK
A9: GK | B9: 1 | C9: {=INDEX(Player_Analysis!$A$2:$A$700,MATCH(1,(Player_Analysis!$B$2:$B$700=A9)*(Player_Analysis!$BB$2:$BB$700=B9),0))} -> Konstantinos Tzolakis | D9: =INDEX(Player_Analysis!$D$2:$D$700,MATCH(C9,Player_Analysis!$A$2:$A$700,0)) -> HUL | E9: =INDEX(Player_Analysis!$E$2:$E$700,MATCH(C9,Player_Analysis!$A$2:$A$700,0)) -> 4.6 | F9: =INDEX(Player_Analysis!$BA$2:$BA$700,MATCH(C9,Player_Analysis!$A$2:$A$700,0)) -> 8.4 | G9: 1 | H9: =INDEX(Player_Analysis!$AT$2:$AT$700,MATCH(C9,Player_Analysis!$A$2:$A$700,0)) -> 8.4 | I9: =IF($G9=1,COUNTIF($G$9:G9,1),"") -> 1 | J9: =IFERROR(INDEX(Player_Analysis!$H$2:$H$596,MATCH($C9,Player_Analysis!$A$2:$A$596,0)),0) -> 1 | L9: Players | M9: =SUM($G$9:$G$160) -> 15 | N9: CHE | O9: =SUMPRODUCT((D9:D598=N9)*G9:G598) -> 0 | P9: =IF(O9>3,"TOO MANY","OK") -> OK
A10: GK | B10: 2 | C10: {=INDEX(Player_Analysis!$A$2:$A$700,MATCH(1,(Player_Analysis!$B$2:$B$700=A10)*(Player_Analysis!$BB$2:$BB$700=B10),0))} -> David Raya Martín | D10: =INDEX(Player_Analysis!$D$2:$D$700,MATCH(C10,Player_Analysis!$A$2:$A$700,0)) -> ARS | E10: =INDEX(Player_Analysis!$E$2:$E$700,MATCH(C10,Player_Analysis!$A$2:$A$700,0)) -> 6 | F10: =INDEX(Player_Analysis!$BA$2:$BA$700,MATCH(C10,Player_Analysis!$A$2:$A$700,0)) -> 6.1779862 | G10: 1 | H10: =INDEX(Player_Analysis!$AT$2:$AT$700,MATCH(C10,Player_Analysis!$A$2:$A$700,0)) -> 6.1779862 | I10: =IF(G10=1,COUNTIF($G$9:G10,1),"") -> 2 | J10: =IFERROR(INDEX(Player_Analysis!$H$2:$H$596,MATCH($C10,Player_Analysis!$A$2:$A$596,0)),0) -> 1 | L10: GK | M10: =SUMPRODUCT((A9:A598="GK")*G9:G598) -> 2 | N10: CRY | O10: =SUMPRODUCT((D9:D598=N10)*G9:G598) -> 0 | P10: =IF(O10>3,"TOO MANY","OK") -> OK
A11: GK | B11: 3 | C11: {=INDEX(Player_Analysis!$A$2:$A$700,MATCH(1,(Player_Analysis!$B$2:$B$700=A11)*(Player_Analysis!$BB$2:$BB$700=B11),0))} -> Lukás Hornícek | D11: =INDEX(Player_Analysis!$D$2:$D$700,MATCH(C11,Player_Analysis!$A$2:$A$700,0)) -> NEW | E11: =INDEX(Player_Analysis!$E$2:$E$700,MATCH(C11,Player_Analysis!$A$2:$A$700,0)) -> 5 | F11: =INDEX(Player_Analysis!$BA$2:$BA$700,MATCH(C11,Player_Analysis!$A$2:$A$700,0)) -> 5.6671727 | G11: 0 | H11: =INDEX(Player_Analysis!$AT$2:$AT$700,MATCH(C11,Player_Analysis!$A$2:$A$700,0)) -> 5.6671727 | I11: =IF(G11=1,COUNTIF($G$9:G11,1),"") | J11: =IFERROR(INDEX(Player_Analysis!$H$2:$H$596,MATCH($C11,Player_Analysis!$A$2:$A$596,0)),0) -> 1 | L11: DEF | M11: =SUMPRODUCT((A9:A605="DEF")*G9:G605) -> 5 | N11: EVE | O11: =SUMPRODUCT((D9:D598=N11)*G9:G598) -> 1 | P11: =IF(O11>3,"TOO MANY","OK") -> OK
A12: GK | B12: 4 | C12: {=INDEX(Player_Analysis!$A$2:$A$700,MATCH(1,(Player_Analysis!$B$2:$B$700=A12)*(Player_Analysis!$BB$2:$BB$700=B12),0))} -> James Trafford | D12: =INDEX(Player_Analysis!$D$2:$D$700,MATCH(C12,Player_Analysis!$A$2:$A$700,0)) -> LEE | E12: =INDEX(Player_Analysis!$E$2:$E$700,MATCH(C12,Player_Analysis!$A$2:$A$700,0)) -> 5 | F12: =INDEX(Player_Analysis!$BA$2:$BA$700,MATCH(C12,Player_Analysis!$A$2:$A$700,0)) -> 5.1845245 | G12: 0 | H12: =INDEX(Player_Analysis!$AT$2:$AT$700,MATCH(C12,Player_Analysis!$A$2:$A$700,0)) -> 5.1845245 | I12: =IF(G12=1,COUNTIF($G$9:G12,1),"") | J12: =IFERROR(INDEX(Player_Analysis!$H$2:$H$596,MATCH($C12,Player_Analysis!$A$2:$A$596,0)),0) -> 1 | L12: MID | M12: =SUMPRODUCT((A9:A605="MID")*G9:G605) -> 5 | N12: FUL | O12: =SUMPRODUCT((D9:D598=N12)*G9:G598) -> 0 | P12: =IF(O12>3,"TOO MANY","OK") -> OK
A13: GK | B13: 5 | C13: {=INDEX(Player_Analysis!$A$2:$A$700,MATCH(1,(Player_Analysis!$B$2:$B$700=A13)*(Player_Analysis!$BB$2:$BB$700=B13),0))} -> Zion Suzuki | D13: =INDEX(Player_Analysis!$D$2:$D$700,MATCH(C13,Player_Analysis!$A$2:$A$700,0)) -> AVL | E13: =INDEX(Player_Analysis!$E$2:$E$700,MATCH(C13,Player_Analysis!$A$2:$A$700,0)) -> 5 | F13: =INDEX(Player_Analysis!$BA$2:$BA$700,MATCH(C13,Player_Analysis!$A$2:$A$700,0)) -> 4.9729316 | G13: 0 | H13: =INDEX(Player_Analysis!$AT$2:$AT$700,MATCH(C13,Player_Analysis!$A$2:$A$700,0)) -> 4.9729316 | I13: =IF(G13=1,COUNTIF($G$9:G13,1),"") | J13: =IFERROR(INDEX(Player_Analysis!$H$2:$H$596,MATCH($C13,Player_Analysis!$A$2:$A$596,0)),0) -> 1 | L13: FWD | M13: =SUMPRODUCT((A9:A605="FWD")*G9:G605) -> 3 | N13: HUL | O13: =SUMPRODUCT((D9:D598=N13)*G9:G598) -> 3 | P13: =IF(O13>3,"TOO MANY","OK") -> OK
A14: GK | B14: 6 | C14: {=INDEX(Player_Analysis!$A$2:$A$700,MATCH(1,(Player_Analysis!$B$2:$B$700=A14)*(Player_Analysis!$BB$2:$BB$700=B14),0))} -> Jordan Pickford | D14: =INDEX(Player_Analysis!$D$2:$D$700,MATCH(C14,Player_Analysis!$A$2:$A$700,0)) -> EVE | E14: =INDEX(Player_Analysis!$E$2:$E$700,MATCH(C14,Player_Analysis!$A$2:$A$700,0)) -> 5.5 | F14: =INDEX(Player_Analysis!$BA$2:$BA$700,MATCH(C14,Player_Analysis!$A$2:$A$700,0)) -> 4.8725152 | G14: 0 | H14: =INDEX(Player_Analysis!$AT$2:$AT$700,MATCH(C14,Player_Analysis!$A$2:$A$700,0)) -> 4.8725152 | I14: =IF(G14=1,COUNTIF($G$9:G14,1),"") | J14: =IFERROR(INDEX(Player_Analysis!$H$2:$H$596,MATCH($C14,Player_Analysis!$A$2:$A$596,0)),0) -> 1 | N14: IPS | O14: =SUMPRODUCT((D9:D598=N14)*G9:G598) -> 0 | P14: =IF(O14>3,"TOO MANY","OK") -> OK
A15: GK | B15: 7 | C15: {=INDEX(Player_Analysis!$A$2:$A$700,MATCH(1,(Player_Analysis!$B$2:$B$700=A15)*(Player_Analysis!$BB$2:$BB$700=B15),0))} -> Gianluigi Donnarumma | D15: =INDEX(Player_Analysis!$D$2:$D$700,MATCH(C15,Player_Analysis!$A$2:$A$700,0)) -> MCI | E15: =INDEX(Player_Analysis!$E$2:$E$700,MATCH(C15,Player_Analysis!$A$2:$A$700,0)) -> 5.5 | F15: =INDEX(Player_Analysis!$BA$2:$BA$700,MATCH(C15,Player_Analysis!$A$2:$A$700,0)) -> 4.662592 | G15: 0 | H15: =INDEX(Player_Analysis!$AT$2:$AT$700,MATCH(C15,Player_Analysis!$A$2:$A$700,0)) -> 4.662592 | I15: =IF(G15=1,COUNTIF($G$9:G15,1),"") | J15: =IFERROR(INDEX(Player_Analysis!$H$2:$H$596,MATCH($C15,Player_Analysis!$A$2:$A$596,0)),0) -> 1 | L15: Eligibility check | M15: =SUMPRODUCT(($G$9:$G$160)*(1-$J$9:$J$160)) -> 0 | N15: LEE | O15: =SUMPRODUCT((D9:D598=N15)*G9:G598) -> 1 | P15: =IF(O15>3,"TOO MANY","OK") -> OK
A16: GK | B16: 8 | C16: {=INDEX(Player_Analysis!$A$2:$A$700,MATCH(1,(Player_Analysis!$B$2:$B$700=A16)*(Player_Analysis!$BB$2:$BB$700=B16),0))} -> Caoimhín Kelleher | D16: =INDEX(Player_Analysis!$D$2:$D$700,MATCH(C16,Player_Analysis!$A$2:$A$700,0)) -> BRE | E16: =INDEX(Player_Analysis!$E$2:$E$700,MATCH(C16,Player_Analysis!$A$2:$A$700,0)) -> 5 | F16: =INDEX(Player_Analysis!$BA$2:$BA$700,MATCH(C16,Player_Analysis!$A$2:$A$700,0)) -> 4.637499 | G16: 0 | H16: =INDEX(Player_Analysis!$AT$2:$AT$700,MATCH(C16,Player_Analysis!$A$2:$A$700,0)) -> 4.637499 | I16: =IF(G16=1,COUNTIF($G$9:G16,1),"") | J16: =IFERROR(INDEX(Player_Analysis!$H$2:$H$596,MATCH($C16,Player_Analysis!$A$2:$A$596,0)),0) -> 1 | N16: LIV | O16: =SUMPRODUCT((D9:D598=N16)*G9:G598) -> 0 | P16: =IF(O16>3,"TOO MANY","OK") -> OK
A17: GK | B17: 9 | C17: {=INDEX(Player_Analysis!$A$2:$A$700,MATCH(1,(Player_Analysis!$B$2:$B$700=A17)*(Player_Analysis!$BB$2:$BB$700=B17),0))} -> Matz Sels | D17: =INDEX(Player_Analysis!$D$2:$D$700,MATCH(C17,Player_Analysis!$A$2:$A$700,0)) -> NFO | E17: =INDEX(Player_Analysis!$E$2:$E$700,MATCH(C17,Player_Analysis!$A$2:$A$700,0)) -> 5 | F17: =INDEX(Player_Analysis!$BA$2:$BA$700,MATCH(C17,Player_Analysis!$A$2:$A$700,0)) -> 4.4162305 | G17: 0 | H17: =INDEX(Player_Analysis!$AT$2:$AT$700,MATCH(C17,Player_Analysis!$A$2:$A$700,0)) -> 4.4162305 | I17: =IF(G17=1,COUNTIF($G$9:G17,1),"") | J17: =IFERROR(INDEX(Player_Analysis!$H$2:$H$596,MATCH($C17,Player_Analysis!$A$2:$A$596,0)),0) -> 1 | L17: Squad Valid | M17: =IF(AND(M9=15,M10=2,M11=5,M12=5,M13=3,M6<=B3,M15=0,MAX(O3:O23)<=3),"YES","NO") -> YES | N17: MCI | O17: =SUMPRODUCT((D9:D598=N17)*G9:G598) -> 3 | P17: =IF(O17>3,"TOO MANY","OK") -> OK
A18: GK | B18: 10 | C18: {=INDEX(Player_Analysis!$A$2:$A$700,MATCH(1,(Player_Analysis!$B$2:$B$700=A18)*(Player_Analysis!$BB$2:$BB$700=B18),0))} -> Alisson Becker | D18: =INDEX(Player_Analysis!$D$2:$D$700,MATCH(C18,Player_Analysis!$A$2:$A$700,0)) -> LIV | E18: =INDEX(Player_Analysis!$E$2:$E$700,MATCH(C18,Player_Analysis!$A$2:$A$700,0)) -> 5.5 | F18: =INDEX(Player_Analysis!$BA$2:$BA$700,MATCH(C18,Player_Analysis!$A$2:$A$700,0)) -> 4.1856979 | G18: 0 | H18: =INDEX(Player_Analysis!$AT$2:$AT$700,MATCH(C18,Player_Analysis!$A$2:$A$700,0)) -> 4.1856979 | I18: =IF(G18=1,COUNTIF($G$9:G18,1),"") | J18: =IFERROR(INDEX(Player_Analysis!$H$2:$H$596,MATCH($C18,Player_Analysis!$A$2:$A$596,0)),0) -> 1 | N18: MUN | O18: =SUMPRODUCT((D9:D598=N18)*G9:G598) -> 2 | P18: =IF(O18>3,"TOO MANY","OK") -> OK
A19: GK | B19: 11 | C19: {=INDEX(Player_Analysis!$A$2:$A$700,MATCH(1,(Player_Analysis!$B$2:$B$700=A19)*(Player_Analysis!$BB$2:$BB$700=B19),0))} -> Bart Verbruggen | D19: =INDEX(Player_Analysis!$D$2:$D$700,MATCH(C19,Player_Analysis!$A$2:$A$700,0)) -> BHA | E19: =INDEX(Player_Analysis!$E$2:$E$700,MATCH(C19,Player_Analysis!$A$2:$A$700,0)) -> 4.5 | F19: =INDEX(Player_Analysis!$BA$2:$BA$700,MATCH(C19,Player_Analysis!$A$2:$A$700,0)) -> 3.9480867 | G19: 0 | H19: =INDEX(Player_Analysis!$AT$2:$AT$700,MATCH(C19,Player_Analysis!$A$2:$A$700,0)) -> 3.9480867 | I19: =IF(G19=1,COUNTIF($G$9:G19,1),"") | J19: =IFERROR(INDEX(Player_Analysis!$H$2:$H$596,MATCH($C19,Player_Analysis!$A$2:$A$596,0)),0) -> 1 | N19: NEW | O19: =SUMPRODUCT((D9:D598=N19)*G9:G598) -> 0 | P19: =IF(O19>3,"TOO MANY","OK") -> OK
A20: GK | B20: 12 | C20: {=INDEX(Player_Analysis!$A$2:$A$700,MATCH(1,(Player_Analysis!$B$2:$B$700=A20)*(Player_Analysis!$BB$2:$BB$700=B20),0))} -> Antonín Kinský | D20: =INDEX(Player_Analysis!$D$2:$D$700,MATCH(C20,Player_Analysis!$A$2:$A$700,0)) -> TOT | E20: =INDEX(Player_Analysis!$E$2:$E$700,MATCH(C20,Player_Analysis!$A$2:$A$700,0)) -> 4.5 | F20: =INDEX(Player_Analysis!$BA$2:$BA$700,MATCH(C20,Player_Analysis!$A$2:$A$700,0)) -> 3.8932944 | G20: 0 | H20: =INDEX(Player_Analysis!$AT$2:$AT$700,MATCH(C20,Player_Analysis!$A$2:$A$700,0)) -> 3.8932944 | I20: =IF(G20=1,COUNTIF($G$9:G20,1),"") | J20: =IFERROR(INDEX(Player_Analysis!$H$2:$H$596,MATCH($C20,Player_Analysis!$A$2:$A$596,0)),0) -> 1 | N20: NFO | O20: =SUMPRODUCT((D9:D598=N20)*G9:G598) -> 0 | P20: =IF(O20>3,"TOO MANY","OK") -> OK
A21: GK | B21: 13 | C21: {=INDEX(Player_Analysis!$A$2:$A$700,MATCH(1,(Player_Analysis!$B$2:$B$700=A21)*(Player_Analysis!$BB$2:$BB$700=B21),0))} -> Emiliano Martínez Romero | D21: =INDEX(Player_Analysis!$D$2:$D$700,MATCH(C21,Player_Analysis!$A$2:$A$700,0)) -> CHE | E21: =INDEX(Player_Analysis!$E$2:$E$700,MATCH(C21,Player_Analysis!$A$2:$A$700,0)) -> 5 | F21: =INDEX(Player_Analysis!$BA$2:$BA$700,MATCH(C21,Player_Analysis!$A$2:$A$700,0)) -> 3.4723371 | G21: 0 | H21: =INDEX(Player_Analysis!$AT$2:$AT$700,MATCH(C21,Player_Analysis!$A$2:$A$700,0)) -> 3.4723371 | I21: =IF(G21=1,COUNTIF($G$9:G21,1),"") | J21: =IFERROR(INDEX(Player_Analysis!$H$2:$H$596,MATCH($C21,Player_Analysis!$A$2:$A$596,0)),0) -> 1 | N21: SUN | O21: =SUMPRODUCT((D9:D598=N21)*G9:G598) -> 0 | P21: =IF(O21>3,"TOO MANY","OK") -> OK
A22: GK | B22: 14 | C22: {=INDEX(Player_Analysis!$A$2:$A$700,MATCH(1,(Player_Analysis!$B$2:$B$700=A22)*(Player_Analysis!$BB$2:$BB$700=B22),0))} -> Marco Bizot | D22: =INDEX(Player_Analysis!$D$2:$D$700,MATCH(C22,Player_Analysis!$A$2:$A$700,0)) -> AVL | E22: =INDEX(Player_Analysis!$E$2:$E$700,MATCH(C22,Player_Analysis!$A$2:$A$700,0)) -> 4.5 | F22: =INDEX(Player_Analysis!$BA$2:$BA$700,MATCH(C22,Player_Analysis!$A$2:$A$700,0)) -> 3.0866472 | G22: 0 | H22: =INDEX(Player_Analysis!$AT$2:$AT$700,MATCH(C22,Player_Analysis!$A$2:$A$700,0)) -> 3.0866472 | I22: =IF(G22=1,COUNTIF($G$9:G22,1),"") | J22: =IFERROR(INDEX(Player_Analysis!$H$2:$H$596,MATCH($C22,Player_Analysis!$A$2:$A$596,0)),0) -> 1 | N22: TOT | O22: =SUMPRODUCT((D9:D598=N22)*G9:G598) -> 0 | P22: =IF(O22>3,"TOO MANY","OK") -> OK
A23: GK | B23: 15 | C23: {=INDEX(Player_Analysis!$A$2:$A$700,MATCH(1,(Player_Analysis!$B$2:$B$700=A23)*(Player_Analysis!$BB$2:$BB$700=B23),0))} -> Robert Lynch Sánchez | D23: =INDEX(Player_Analysis!$D$2:$D$700,MATCH(C23,Player_Analysis!$A$2:$A$700,0)) -> CHE | E23: =INDEX(Player_Analysis!$E$2:$E$700,MATCH(C23,Player_Analysis!$A$2:$A$700,0)) -> 4.9 | F23: =INDEX(Player_Analysis!$BA$2:$BA$700,MATCH(C23,Player_Analysis!$A$2:$A$700,0)) -> 2.8957685 | G23: 0 | H23: =INDEX(Player_Analysis!$AT$2:$AT$700,MATCH(C23,Player_Analysis!$A$2:$A$700,0)) -> 2.8957685 | I23: =IF(G23=1,COUNTIF($G$9:G23,1),"") | J23: =IFERROR(INDEX(Player_Analysis!$H$2:$H$596,MATCH($C23,Player_Analysis!$A$2:$A$596,0)),0) -> 0
A24: GK | B24: 16 | C24: {=INDEX(Player_Analysis!$A$2:$A$700,MATCH(1,(Player_Analysis!$B$2:$B$700=A24)*(Player_Analysis!$BB$2:$BB$700=B24),0))} -> Kjell Scherpen | D24: =INDEX(Player_Analysis!$D$2:$D$700,MATCH(C24,Player_Analysis!$A$2:$A$700,0)) -> IPS | E24: =INDEX(Player_Analysis!$E$2:$E$700,MATCH(C24,Player_Analysis!$A$2:$A$700,0)) -> 4.5 | F24: =INDEX(Player_Analysis!$BA$2:$BA$700,MATCH(C24,Player_Analysis!$A$2:$A$700,0)) -> 2.8123724 | G24: 0 | H24: =INDEX(Player_Analysis!$AT$2:$AT$700,MATCH(C24,Player_Analysis!$A$2:$A$700,0)) -> 2.8123724 | I24: =IF(G24=1,COUNTIF($G$9:G24,1),"") | J24: =IFERROR(INDEX(Player_Analysis!$H$2:$H$596,MATCH($C24,Player_Analysis!$A$2:$A$596,0)),0) -> 1
A25: GK | B25: 17 | C25: {=INDEX(Player_Analysis!$A$2:$A$700,MATCH(1,(Player_Analysis!$B$2:$B$700=A25)*(Player_Analysis!$BB$2:$BB$700=B25),0))} -> Senne Lammens | D25: =INDEX(Player_Analysis!$D$2:$D$700,MATCH(C25,Player_Analysis!$A$2:$A$700,0)) -> MUN | E25: =INDEX(Player_Analysis!$E$2:$E$700,MATCH(C25,Player_Analysis!$A$2:$A$700,0)) -> 5 | F25: =INDEX(Player_Analysis!$BA$2:$BA$700,MATCH(C25,Player_Analysis!$A$2:$A$700,0)) -> 2.774628 | G25: 0 | H25: =INDEX(Player_Analysis!$AT$2:$AT$700,MATCH(C25,Player_Analysis!$A$2:$A$700,0)) -> 2.774628 | I25: =IF(G25=1,COUNTIF($G$9:G25,1),"") | J25: =IFERROR(INDEX(Player_Analysis!$H$2:$H$596,MATCH($C25,Player_Analysis!$A$2:$A$596,0)),0) -> 1
A26: GK | B26: 18 | C26: {=INDEX(Player_Analysis!$A$2:$A$700,MATCH(1,(Player_Analysis!$B$2:$B$700=A26)*(Player_Analysis!$BB$2:$BB$700=B26),0))} -> Dean Henderson | D26: =INDEX(Player_Analysis!$D$2:$D$700,MATCH(C26,Player_Analysis!$A$2:$A$700,0)) -> CRY | E26: =INDEX(Player_Analysis!$E$2:$E$700,MATCH(C26,Player_Analysis!$A$2:$A$700,0)) -> 5 | F26: =INDEX(Player_Analysis!$BA$2:$BA$700,MATCH(C26,Player_Analysis!$A$2:$A$700,0)) -> 2.7741732 | G26: 0 | H26: =INDEX(Player_Analysis!$AT$2:$AT$700,MATCH(C26,Player_Analysis!$A$2:$A$700,0)) -> 2.7741732 | J26: =IFERROR(INDEX(Player_Analysis!$H$2:$H$596,MATCH($C26,Player_Analysis!$A$2:$A$596,0)),0) -> 1
A27: GK | B27: 19 | C27: {=INDEX(Player_Analysis!$A$2:$A$700,MATCH(1,(Player_Analysis!$B$2:$B$700=A27)*(Player_Analysis!$BB$2:$BB$700=B27),0))} -> Đorđe Petrović | D27: =INDEX(Player_Analysis!$D$2:$D$700,MATCH(C27,Player_Analysis!$A$2:$A$700,0)) -> BOU | E27: =INDEX(Player_Analysis!$E$2:$E$700,MATCH(C27,Player_Analysis!$A$2:$A$700,0)) -> 4.5 | F27: =INDEX(Player_Analysis!$BA$2:$BA$700,MATCH(C27,Player_Analysis!$A$2:$A$700,0)) -> 2.5647797 | G27: 0 | H27: =INDEX(Player_Analysis!$AT$2:$AT$700,MATCH(C27,Player_Analysis!$A$2:$A$700,0)) -> 2.5647797 | J27: =IFERROR(INDEX(Player_Analysis!$H$2:$H$596,MATCH($C27,Player_Analysis!$A$2:$A$596,0)),0) -> 1
A28: GK | B28: 20 | C28: {=INDEX(Player_Analysis!$A$2:$A$700,MATCH(1,(Player_Analysis!$B$2:$B$700=A28)*(Player_Analysis!$BB$2:$BB$700=B28),0))} -> Carl Rushworth | D28: =INDEX(Player_Analysis!$D$2:$D$700,MATCH(C28,Player_Analysis!$A$2:$A$700,0)) -> COV | E28: =INDEX(Player_Analysis!$E$2:$E$700,MATCH(C28,Player_Analysis!$A$2:$A$700,0)) -> 4.5 | F28: =INDEX(Player_Analysis!$BA$2:$BA$700,MATCH(C28,Player_Analysis!$A$2:$A$700,0)) -> 2.499612 | G28: 0 | H28: =INDEX(Player_Analysis!$AT$2:$AT$700,MATCH(C28,Player_Analysis!$A$2:$A$700,0)) -> 2.499612 | J28: =IFERROR(INDEX(Player_Analysis!$H$2:$H$596,MATCH($C28,Player_Analysis!$A$2:$A$596,0)),0) -> 1
A29: GK | B29: 21 | C29: {=INDEX(Player_Analysis!$A$2:$A$700,MATCH(1,(Player_Analysis!$B$2:$B$700=A29)*(Player_Analysis!$BB$2:$BB$700=B29),0))} -> Bernd Leno | D29: =INDEX(Player_Analysis!$D$2:$D$700,MATCH(C29,Player_Analysis!$A$2:$A$700,0)) -> FUL | E29: =INDEX(Player_Analysis!$E$2:$E$700,MATCH(C29,Player_Analysis!$A$2:$A$700,0)) -> 4.5 | F29: =INDEX(Player_Analysis!$BA$2:$BA$700,MATCH(C29,Player_Analysis!$A$2:$A$700,0)) -> 2.4639849 | G29: 0 | H29: =INDEX(Player_Analysis!$AT$2:$AT$700,MATCH(C29,Player_Analysis!$A$2:$A$700,0)) -> 2.4639849 | J29: =IFERROR(INDEX(Player_Analysis!$H$2:$H$596,MATCH($C29,Player_Analysis!$A$2:$A$596,0)),0) -> 1
A30: GK | B30: 22 | C30: {=INDEX(Player_Analysis!$A$2:$A$700,MATCH(1,(Player_Analysis!$B$2:$B$700=A30)*(Player_Analysis!$BB$2:$BB$700=B30),0))} -> Kepa Arrizabalaga Revuelta | D30: =INDEX(Player_Analysis!$D$2:$D$700,MATCH(C30,Player_Analysis!$A$2:$A$700,0)) -> ARS | E30: =INDEX(Player_Analysis!$E$2:$E$700,MATCH(C30,Player_Analysis!$A$2:$A$700,0)) -> 4.9 | F30: =INDEX(Player_Analysis!$BA$2:$BA$700,MATCH(C30,Player_Analysis!$A$2:$A$700,0)) -> 0 | G30: 0 | H30: =INDEX(Player_Analysis!$AT$2:$AT$700,MATCH(C30,Player_Analysis!$A$2:$A$700,0)) -> 0 | J30: =IFERROR(INDEX(Player_Analysis!$H$2:$H$596,MATCH($C30,Player_Analysis!$A$2:$A$596,0)),0) -> 1
A31: GK | B31: 23 | C31: {=INDEX(Player_Analysis!$A$2:$A$700,MATCH(1,(Player_Analysis!$B$2:$B$700=A31)*(Player_Analysis!$BB$2:$BB$700=B31),0))} -> Illan Meslier | D31: =INDEX(Player_Analysis!$D$2:$D$700,MATCH(C31,Player_Analysis!$A$2:$A$700,0)) -> ARS | E31: =INDEX(Player_Analysis!$E$2:$E$700,MATCH(C31,Player_Analysis!$A$2:$A$700,0)) -> 4.9 | F31: =INDEX(Player_Analysis!$BA$2:$BA$700,MATCH(C31,Player_Analysis!$A$2:$A$700,0)) -> 0 | G31: 0 | H31: =INDEX(Player_Analysis!$AT$2:$AT$700,MATCH(C31,Player_Analysis!$A$2:$A$700,0)) -> 0 | J31: =IFERROR(INDEX(Player_Analysis!$H$2:$H$596,MATCH($C31,Player_Analysis!$A$2:$A$596,0)),0) -> 1
A32: GK | B32: 24 | C32: {=INDEX(Player_Analysis!$A$2:$A$700,MATCH(1,(Player_Analysis!$B$2:$B$700=A32)*(Player_Analysis!$BB$2:$BB$700=B32),0))} -> Fraser Forster | D32: =INDEX(Player_Analysis!$D$2:$D$700,MATCH(C32,Player_Analysis!$A$2:$A$700,0)) -> BOU | E32: =INDEX(Player_Analysis!$E$2:$E$700,MATCH(C32,Player_Analysis!$A$2:$A$700,0)) -> 4 | F32: =INDEX(Player_Analysis!$BA$2:$BA$700,MATCH(C32,Player_Analysis!$A$2:$A$700,0)) -> 0 | G32: 0 | H32: =INDEX(Player_Analysis!$AT$2:$AT$700,MATCH(C32,Player_Analysis!$A$2:$A$700,0)) -> 0 | J32: =IFERROR(INDEX(Player_Analysis!$H$2:$H$596,MATCH($C32,Player_Analysis!$A$2:$A$596,0)),0) -> 1
A33: GK | B33: 25 | C33: {=INDEX(Player_Analysis!$A$2:$A$700,MATCH(1,(Player_Analysis!$B$2:$B$700=A33)*(Player_Analysis!$BB$2:$BB$700=B33),0))} -> Will Dennis | D33: =INDEX(Player_Analysis!$D$2:$D$700,MATCH(C33,Player_Analysis!$A$2:$A$700,0)) -> BOU | E33: =INDEX(Player_Analysis!$E$2:$E$700,MATCH(C33,Player_Analysis!$A$2:$A$700,0)) -> 4 | F33: =INDEX(Player_Analysis!$BA$2:$BA$700,MATCH(C33,Player_Analysis!$A$2:$A$700,0)) -> 0 | G33: 0 | H33: =INDEX(Player_Analysis!$AT$2:$AT$700,MATCH(C33,Player_Analysis!$A$2:$A$700,0)) -> 0 | J33: =IFERROR(INDEX(Player_Analysis!$H$2:$H$596,MATCH($C33,Player_Analysis!$A$2:$A$596,0)),0) -> 0
A34: GK | B34: 26 | C34: {=INDEX(Player_Analysis!$A$2:$A$700,MATCH(1,(Player_Analysis!$B$2:$B$700=A34)*(Player_Analysis!$BB$2:$BB$700=B34),0))} -> Michele Di Gregorio | D34: =INDEX(Player_Analysis!$D$2:$D$700,MATCH(C34,Player_Analysis!$A$2:$A$700,0)) -> BOU | E34: =INDEX(Player_Analysis!$E$2:$E$700,MATCH(C34,Player_Analysis!$A$2:$A$700,0)) -> 4.5 | F34: =INDEX(Player_Analysis!$BA$2:$BA$700,MATCH(C34,Player_Analysis!$A$2:$A$700,0)) -> 0 | G34: 0 | H34: =INDEX(Player_Analysis!$AT$2:$AT$700,MATCH(C34,Player_Analysis!$A$2:$A$700,0)) -> 0 | J34: =IFERROR(INDEX(Player_Analysis!$H$2:$H$596,MATCH($C34,Player_Analysis!$A$2:$A$596,0)),0) -> 1
A35: GK | B35: 27 | C35: {=INDEX(Player_Analysis!$A$2:$A$700,MATCH(1,(Player_Analysis!$B$2:$B$700=A35)*(Player_Analysis!$BB$2:$BB$700=B35),0))} -> Hákon Rafn Valdimarsson | D35: =INDEX(Player_Analysis!$D$2:$D$700,MATCH(C35,Player_Analysis!$A$2:$A$700,0)) -> BRE | E35: =INDEX(Player_Analysis!$E$2:$E$700,MATCH(C35,Player_Analysis!$A$2:$A$700,0)) -> 4.5 | F35: =INDEX(Player_Analysis!$BA$2:$BA$700,MATCH(C35,Player_Analysis!$A$2:$A$700,0)) -> 0 | G35: 0 | H35: =INDEX(Player_Analysis!$AT$2:$AT$700,MATCH(C35,Player_Analysis!$A$2:$A$700,0)) -> 0 | J35: =IFERROR(INDEX(Player_Analysis!$H$2:$H$596,MATCH($C35,Player_Analysis!$A$2:$A$596,0)),0) -> 1
A36: GK | B36: 28 | C36: {=INDEX(Player_Analysis!$A$2:$A$700,MATCH(1,(Player_Analysis!$B$2:$B$700=A36)*(Player_Analysis!$BB$2:$BB$700=B36),0))} -> Jason Steele | D36: =INDEX(Player_Analysis!$D$2:$D$700,MATCH(C36,Player_Analysis!$A$2:$A$700,0)) -> BHA | E36: =INDEX(Player_Analysis!$E$2:$E$700,MATCH(C36,Player_Analysis!$A$2:$A$700,0)) -> 4 | F36: =INDEX(Player_Analysis!$BA$2:$BA$700,MATCH(C36,Player_Analysis!$A$2:$A$700,0)) -> 0 | G36: 0 | H36: =INDEX(Player_Analysis!$AT$2:$AT$700,MATCH(C36,Player_Analysis!$A$2:$A$700,0)) -> 0 | J36: =IFERROR(INDEX(Player_Analysis!$H$2:$H$596,MATCH($C36,Player_Analysis!$A$2:$A$596,0)),0) -> 1
A37: GK | B37: 29 | C37: {=INDEX(Player_Analysis!$A$2:$A$700,MATCH(1,(Player_Analysis!$B$2:$B$700=A37)*(Player_Analysis!$BB$2:$BB$700=B37),0))} -> Filip Jörgensen | D37: =INDEX(Player_Analysis!$D$2:$D$700,MATCH(C37,Player_Analysis!$A$2:$A$700,0)) -> CHE | E37: =INDEX(Player_Analysis!$E$2:$E$700,MATCH(C37,Player_Analysis!$A$2:$A$700,0)) -> 5 | F37: =INDEX(Player_Analysis!$BA$2:$BA$700,MATCH(C37,Player_Analysis!$A$2:$A$700,0)) -> 0 | G37: 0 | H37: =INDEX(Player_Analysis!$AT$2:$AT$700,MATCH(C37,Player_Analysis!$A$2:$A$700,0)) -> 0 | J37: =IFERROR(INDEX(Player_Analysis!$H$2:$H$596,MATCH($C37,Player_Analysis!$A$2:$A$596,0)),0) -> 0
A38: GK | B38: 30 | C38: {=INDEX(Player_Analysis!$A$2:$A$700,MATCH(1,(Player_Analysis!$B$2:$B$700=A38)*(Player_Analysis!$BB$2:$BB$700=B38),0))} -> Mike Penders | D38: =INDEX(Player_Analysis!$D$2:$D$700,MATCH(C38,Player_Analysis!$A$2:$A$700,0)) -> CHE | E38: =INDEX(Player_Analysis!$E$2:$E$700,MATCH(C38,Player_Analysis!$A$2:$A$700,0)) -> 4.5 | F38: =INDEX(Player_Analysis!$BA$2:$BA$700,MATCH(C38,Player_Analysis!$A$2:$A$700,0)) -> 0 | G38: 0 | H38: =INDEX(Player_Analysis!$AT$2:$AT$700,MATCH(C38,Player_Analysis!$A$2:$A$700,0)) -> 0 | J38: =IFERROR(INDEX(Player_Analysis!$H$2:$H$596,MATCH($C38,Player_Analysis!$A$2:$A$596,0)),0) -> 1
A39: DEF | B39: 1 | C39: {=INDEX(Player_Analysis!$A$2:$A$700,MATCH(1,(Player_Analysis!$B$2:$B$700=A39)*(Player_Analysis!$BB$2:$BB$700=B39),0))} -> John Egan | D39: =INDEX(Player_Analysis!$D$2:$D$700,MATCH(C39,Player_Analysis!$A$2:$A$700,0)) -> HUL | E39: =INDEX(Player_Analysis!$E$2:$E$700,MATCH(C39,Player_Analysis!$A$2:$A$700,0)) -> 4.1 | F39: =INDEX(Player_Analysis!$BA$2:$BA$700,MATCH(C39,Player_Analysis!$A$2:$A$700,0)) -> 10.502855 | G39: 1 | H39: =INDEX(Player_Analysis!$AT$2:$AT$700,MATCH(C39,Player_Analysis!$A$2:$A$700,0)) -> 10.502855 | I39: =IF(G39=1,COUNTIF($G$9:G39,1),"") -> 3 | J39: =IFERROR(INDEX(Player_Analysis!$H$2:$H$596,MATCH($C39,Player_Analysis!$A$2:$A$596,0)),0) -> 1
A40: DEF | B40: 2 | C40: {=INDEX(Player_Analysis!$A$2:$A$700,MATCH(1,(Player_Analysis!$B$2:$B$700=A40)*(Player_Analysis!$BB$2:$BB$700=B40),0))} -> Semi Ajayi | D40: =INDEX(Player_Analysis!$D$2:$D$700,MATCH(C40,Player_Analysis!$A$2:$A$700,0)) -> HUL | E40: =INDEX(Player_Analysis!$E$2:$E$700,MATCH(C40,Player_Analysis!$A$2:$A$700,0)) -> 4.1 | F40: =INDEX(Player_Analysis!$BA$2:$BA$700,MATCH(C40,Player_Analysis!$A$2:$A$700,0)) -> 10.364444 | G40: 1 | H40: =INDEX(Player_Analysis!$AT$2:$AT$700,MATCH(C40,Player_Analysis!$A$2:$A$700,0)) -> 10.364444 | I40: =IF(G40=1,COUNTIF($G$9:G40,1),"") -> 4 | J40: =IFERROR(INDEX(Player_Analysis!$H$2:$H$596,MATCH($C40,Player_Analysis!$A$2:$A$596,0)),0) -> 1
...

Sheet FPL_Raw_Data
A1: element_type | B1: first_name | C1: second_name | D1: id | E1: form | F1: now_cost | G1: points_per_game | H1: selected_by_percent | I1: team | J1: total_points | K1: minutes | L1: goals_scored | M1: assists | N1: clean_sheets | O1: goals_conceded | P1: saves | Q1: bonus | R1: bps | S1: defensive_contribution | T1: starts | U1: expected_goals | V1: expected_assists | W1: expected_goal_involvements | X1: expected_goals_conceded | Y1: status | Z1: can_select | AA1: Player
A2: 1 | B2: David | C2: Raya Martín | D2: 1 | E2: 5 | F2: 60 | G2: 5 | H2: 38.7 | I2: 1 | J2: 15 | K2: 270 | L2: 0 | M2: 0 | N2: 2 | O2: 1 | P2: 5 | Q2: 0 | R2: 60 | S2: 0 | T2: 3 | U2: 0 | V2: 0.01 | W2: 0.01 | X2: 0.92 | Y2: a | Z2: TRUE | AA2: =B2&" "&C2 -> David Raya Martín
A3: 1 | B3: Kepa | C3: Arrizabalaga Revuelta | D3: 2 | E3: 0 | F3: 49 | G3: 0 | H3: 0.1 | I3: 1 | J3: 0 | K3: 0 | L3: 0 | M3: 0 | N3: 0 | O3: 0 | P3: 0 | Q3: 0 | R3: 0 | S3: 0 | T3: 0 | U3: 0 | V3: 0 | W3: 0 | X3: 0 | Y3: a | Z3: TRUE | AA3: =B3&" "&C3 -> Kepa Arrizabalaga Revuelta
A4: 1 | B4: Illan | C4: Meslier | D4: 3 | E4: 0 | F4: 49 | G4: 0 | H4: 0 | I4: 1 | J4: 0 | K4: 0 | L4: 0 | M4: 0 | N4: 0 | O4: 0 | P4: 0 | Q4: 0 | R4: 0 | S4: 0 | T4: 0 | U4: 0 | V4: 0 | W4: 0 | X4: 0 | Y4: a | Z4: TRUE | AA4: =B4&" "&C4 -> Illan Meslier
A5: 2 | B5: Gabriel | C5: dos Santos Magalhães | D5: 4 | E5: 5 | F5: 80 | G5: 5 | H5: 25.1 | I5: 1 | J5: 15 | K5: 270 | L5: 0 | M5: 0 | N5: 2 | O5: 1 | P5: 0 | Q5: 0 | R5: 54 | S5: 21 | T5: 3 | U5: 0.49 | V5: 0.05 | W5: 0.54 | X5: 0.92 | Y5: a | Z5: TRUE | AA5: =B5&" "&C5 -> Gabriel dos Santos Magalhães
A6: 2 | B6: Jurriën | C6: Timber | D6: 5 | E6: 0 | F6: 65 | G6: 0 | H6: 0.1 | I6: 1 | J6: 0 | K6: 0 | L6: 0 | M6: 0 | N6: 0 | O6: 0 | P6: 0 | Q6: 0 | R6: 0 | S6: 0 | T6: 0 | U6: 0 | V6: 0 | W6: 0 | X6: 0 | Y6: d | Z6: TRUE | AA6: =B6&" "&C6 -> Jurriën Timber
A7: 2 | B7: William | C7: Saliba | D7: 6 | E7: 0 | F7: 60 | G7: 0 | H7: 0.2 | I7: 1 | J7: 0 | K7: 0 | L7: 0 | M7: 0 | N7: 0 | O7: 0 | P7: 0 | Q7: 0 | R7: 0 | S7: 0 | T7: 0 | U7: 0 | V7: 0 | W7: 0 | X7: 0 | Y7: i | Z7: TRUE | AA7: =B7&" "&C7 -> William Saliba
A8: 3 | B8: Myles | C8: Lewis-Skelly | D8: 7 | E8: 2.7 | F8: 55 | G8: 2.7 | H8: 0.7 | I8: 1 | J8: 8 | K8: 226 | L8: 0 | M8: 0 | N8: 2 | O8: 1 | P8: 0 | Q8: 0 | R8: 35 | S8: 14 | T8: 3 | U8: 0.16 | V8: 0.23 | W8: 0.39 | X8: 0.79 | Y8: a | Z8: TRUE | AA8: =B8&" "&C8 -> Myles Lewis-Skelly
A9: 2 | B9: Riccardo | C9: Calafiori | D9: 8 | E9: 7.3 | F9: 57 | G9: 7.3 | H9: 46.9 | I9: 1 | J9: 22 | K9: 236 | L9: 0 | M9: 2 | N9: 2 | O9: 1 | P9: 0 | Q9: 2 | R9: 61 | S9: 9 | T9: 3 | U9: 0.54 | V9: 0.58 | W9: 1.12 | X9: 0.65 | Y9: a | Z9: TRUE | AA9: =B9&" "&C9 -> Riccardo Calafiori
A10: 2 | B10: Piero | C10: Hincapié | D10: 9 | E10: 0.7 | F10: 53 | G10: 1 | H10: 1.1 | I10: 1 | J10: 2 | K10: 32 | L10: 0 | M10: 0 | N10: 0 | O10: 0 | P10: 0 | Q10: 0 | R10: 6 | S10: 3 | T10: 0 | U10: 0 | V10: 0 | W10: 0 | X10: 0.28 | Y10: a | Z10: TRUE | AA10: =B10&" "&C10 -> Piero Hincapié
A11: 2 | B11: Benjamin | C11: White | D11: 10 | E11: 6.7 | F11: 55 | G11: 6.7 | H11: 7.7 | I11: 1 | J11: 20 | K11: 270 | L11: 0 | M11: 1 | N11: 2 | O11: 1 | P11: 0 | Q11: 3 | R11: 74 | S11: 15 | T11: 3 | U11: 0.18 | V11: 0.29 | W11: 0.47 | X11: 0.92 | Y11: a | Z11: TRUE | AA11: =B11&" "&C11 -> Benjamin White
A12: 2 | B12: Cristhian | C12: Mosquera | D12: 11 | E12: 4 | F12: 54 | G12: 6 | H12: 3.8 | I12: 1 | J12: 12 | K12: 168 | L12: 0 | M12: 0 | N12: 2 | O12: 0 | P12: 0 | Q12: 0 | R12: 52 | S12: 10 | T12: 2 | U12: 0 | V12: 0.01 | W12: 0.01 | X12: 0.53 | Y12: d | Z12: TRUE | AA12: =B12&" "&C12 -> Cristhian Mosquera
A13: 3 | B13: Bukayo | C13: Saka | D13: 12 | E13: 7.3 | F13: 95 | G13: 7.3 | H13: 11.3 | I13: 1 | J13: 22 | K13: 246 | L13: 2 | M13: 0 | N13: 2 | O13: 1 | P13: 0 | Q13: 4 | R13: 95 | S13: 22 | T13: 3 | U13: 1.5 | V13: 0.35 | W13: 1.85 | X13: 0.78 | Y13: a | Z13: TRUE | AA13: =B13&" "&C13 -> Bukayo Saka
... A655: 4 | B655: Juan | C655: Angulo | D655: 651 | E655: 0 | F655: 45 | G655: 0 | H655: 0.3 | I655: 20 | J655: 0 | K655: 0 | L655: 0 | M655: 0 | N655: 0 | O655: 0 | P655: 0 | Q655: 0 | R655: 0 | S655: 0 | T655: 0 | U655: 0 | V655: 0 | W655: 0 | X655: 0 | Y655: a | Z655: TRUE | AA655: =B655&" "&C655 -> Juan Angulo

Sheet Player_Analysis
A1: Player | B1: Position | C1: Team | D1: Team Code | E1: Price | F1: Availability Status | G1: Can Select | H1: Player Eligible | I1: Minutes | J1: Minutes / 90 | K1: Start % | L1: Total Points | M1: PPG | N1: Form | O1: xG | P1: xA | Q1: xGI | R1: Points/90 | S1: xG/90 | T1: xA/90 | U1: xGI/90 | V1: Points/£m | W1: xGI/£m | X1: Fixture Score | Y1: Fixture Adjustment | Z1: Starts | AA1: Defensive Contributions | AB1: DC Potential | AC1: Bonus | AD1: BPS | AE1: Clean Sheets | AF1: Goals | AG1: Assists | AH1: Expected Goal Points / 90 | AI1: Expected Assist Points / 90 | AJ1: Expected Appearance Points / 90 | AK1: Expected DC Points / 90 | AL1: Clean Sheet Rate | AM1: Expected Clean Sheet Points / 90 | AN1: Bonus / Start | AO1: Points/90 score | AP1: xGI/90 Score | AQ1: Points/£m Score | AR1: xGI/£m Score | AS1: Start Score | AT1: Model Expected Points | AU1: Fixture Adjusted Points / 90 | AV1: Expected Points / £m | AW1: Attacking score | AX1: Defensive score | AY1: Reliability Score | AZ1: Fixture Adjusted Score | BA1: Model Score | BB1: Position Rank | BC1: Recommendation | BD1: Solver Score | BE1: Model Overall Rank | BF1: Model Position Rank | BG1: Model Score2
A2: =tblPlayers[first_name]&" "&tblPlayers[second_name] -> David Raya Martín | B2: =_xlfn.SWITCH(tblPlayers[element_type],1,"GK",2,"DEF",3,"MID",4,"FWD") -> GK | C2: =tblPlayers[team] -> 1 | D2: =INDEX(tblTeams[Column1.short_name],MATCH(C2,tblTeams[Column1.id],0)) -> ARS | E2: =INDEX(FPL_Raw_Data!$F:$F,MATCH(A2,FPL_Raw_Data!$AA:$AA,0))/10 -> 6 | F2: =tblPlayers[[#This Row],[status]] -> a | G2: =tblPlayers[[#This Row],[can_select]] -> TRUE | H2: =IF(AND(Table8[[#This Row],[Availability Status]]="a",Table8[[#This Row],[Can Select]]=TRUE),1,0) -> 1 | I2: =tblPlayers[minutes] -> 270 | J2: =Table8[[#This Row],[Minutes]]/90 -> 3 | K2: =IFERROR(Z2/(FIXTURE_ANALYSIS!$B$1-1),0) -> 1 | L2: =tblPlayers[total_points] -> 15 | M2: =tblPlayers[points_per_game] -> 5 | N2: =tblPlayers[form] -> 5 | O2: =tblPlayers[expected_goals] -> 0 | P2: =tblPlayers[expected_assists] -> 0.01 | Q2: =tblPlayers[expected_goal_involvements] -> 0.01 | R2: =IF(I2=0,0,L2/I2*90) -> 5 | S2: =IF(I2=0,0,O2/I2*90) -> 0 | T2: =IF(I2=0,0,P2/I2*90) -> 0.0033333333 | U2: =IF(I2=0,0,Q2/I2*90) -> 0.0033333333 | V2: =IF(E2=0,0,L2/E2) -> 2.5 | W2: =IF(E2=0,0,Q2/E2) -> 0.0016666667 | X2: =IFERROR(IF(OR($B2="MID",$B2="FWD"),INDEX(FIXTURE_ANALYSIS!$Q:$Q,MATCH($D2,FIXTURE_ANALYSIS!$A:$A,0)),INDEX(FIXTURE_ANALYSIS!$R:$R,MATCH($D2,FIXTURE_ANALYSIS!$A:$A,0))),1) -> 1.1808552 | Y2: =X2 -> 1.1808552 | Z2: =INDEX(FPL_Raw_Data!$T:$T,MATCH(A2,FPL_Raw_Data!$AA:$AA,0)) -> 3 | AA2: =INDEX(FPL_Raw_Data!$S:$S,MATCH(A2,FPL_Raw_Data!$AA:$AA,0)) -> 0 | AB2: =IF(B2="DEF",MIN(AA2/10,1),IF(OR(B2="MID",B2="FWD"),MIN(AA2/12,1),0)) -> 0 | AC2: =INDEX(FPL_Raw_Data!$Q:$Q,MATCH(A2,FPL_Raw_Data!$AA:$AA,0)) -> 0 | AD2: =INDEX(FPL_Raw_Data!$R:$R,MATCH(A2,FPL_Raw_Data!$AA:$AA,0)) -> 60 | AE2: =INDEX(FPL_Raw_Data!$N:$N,MATCH(A2,FPL_Raw_Data!$AA:$AA,0)) -> 2 | AF2: =INDEX(FPL_Raw_Data!$L:$L,MATCH(A2,FPL_Raw_Data!$AA:$AA,0)) -> 0 | AG2: =INDEX(FPL_Raw_Data!$M:$M,MATCH(A2,FPL_Raw_Data!$AA:$AA,0)) -> 0 | AH2: =IF(B2="GK",S2*10,IF(B2="DEF",S2*6,IF(B2="MID",S2*5,S2*4))) -> 0 | AI2: =T2*3 -> 0.01 | AJ2: =K2*2 -> 2 | AK2: =AB2*2 -> 0 | AL2: =IFERROR(AE2/Z2,0) -> 0.66666667 | AM2: =IF(OR(B2="GK",B2="DEF"),AL2*4,IF(B2="MID",AL2*1,0)) -> 2.6666667 | AN2: =IFERROR(AC2/Z2,0) -> 0 | AO2: =IFERROR(_xlfn.PERCENTRANK.INC($R$2:$R$700,R2)*100,0) -> 75.4 | AP2: =IFERROR(_xlfn.PERCENTRANK.INC($U$2:$U$700,U2)*100,0) -> 50.8 | AQ2: =IFERROR(_xlfn.PERCENTRANK.INC($V$2:$V$700,V2)*100,0) -> 91.7 | AR2: =IFERROR(_xlfn.PERCENTRANK.INC($W$2:$W$700,W2)*100,0) -> 51 | AS2: =K2*100 -> 100 | AT2: =IFERROR(INDEX(Player_Model!$BC$2:$BC$596,MATCH($A2,Player_Model!$A$2:$A$596,0)),0) -> 6.1779862 | AU2: =Table8[[#This Row],[Model Expected Points]]*Table8[[#This Row],[Fixture Adjustment]] -> 7.2953071 | AV2: =Table8[[#This Row],[Fixture Adjusted Points / 90]]/Table8[[#This Row],[Price]] -> 1.2158845 | AW2: =IF(OR(B2="MID",B2="FWD"),AVERAGE(AO2,AP2),IF(B2="DEF",AP2,0)) -> 0 | AX2: =IF(B2="GK",AVERAGE(AS2,X2),IF(B2="DEF",AVERAGE(AB2,X2),IF(B2="MID",AB2,0))) -> 50.590428 | AY2: =AS2 -> 100 | AZ2: =X2 -> 1.1808552 | BA2: =Table8[[#This Row],[Model Score2]] -> 6.1779862 | BB2: =IFERROR(INDEX(Player_Model!$BG$2:$BG$596,MATCH($A2,Player_Model!$A$2:$A$596,0)),"") -> 2 | BC2: =IF(BB2=1,"TOP PICK",IF(BB2<=5,"STRONG PICK",IF(BB2<=10,"CONSIDER","AVOID"))) -> STRONG PICK | BD2: =IF(H2=1,Table8[[#This Row],[Model Score]],-10000) -> 6.1779862 | BE2: =IFERROR(INDEX(Player_Model!$BF$2:$BF$596,MATCH($A2,Player_Model!$A$2:$A$596,0)),"") -> 38 | BF2: =IFERROR(INDEX(Player_Model!$BG$2:$BG$596,MATCH($A2,Player_Model!$A$2:$A$596,0)),"") -> 2 | BG2: =IFERROR(INDEX(Player_Model!$BE$2:$BE$596,MATCH($A2,Player_Model!$A$2:$A$596,0)),0) -> 6.1779862
A3: =tblPlayers[first_name]&" "&tblPlayers[second_name] -> Kepa Arrizabalaga Revuelta | B3: =_xlfn.SWITCH(tblPlayers[element_type],1,"GK",2,"DEF",3,"MID",4,"FWD") -> GK | C3: =tblPlayers[team] -> 1 | D3: =INDEX(tblTeams[Column1.short_name],MATCH(C3,tblTeams[Column1.id],0)) -> ARS | E3: =INDEX(FPL_Raw_Data!$F:$F,MATCH(A3,FPL_Raw_Data!$AA:$AA,0))/10 -> 4.9 | F3: =tblPlayers[[#This Row],[status]] -> a | G3: =tblPlayers[[#This Row],[can_select]] -> TRUE | H3: =IF(AND(Table8[[#This Row],[Availability Status]]="a",Table8[[#This Row],[Can Select]]=TRUE),1,0) -> 1 | I3: =tblPlayers[minutes] -> 0 | J3: =Table8[[#This Row],[Minutes]]/90 -> 0 | K3: =IFERROR(Z3/(FIXTURE_ANALYSIS!$B$1-1),0) -> 0 | L3: =tblPlayers[total_points] -> 0 | M3: =tblPlayers[points_per_game] -> 0 | N3: =tblPlayers[form] -> 0 | O3: =tblPlayers[expected_goals] -> 0 | P3: =tblPlayers[expected_assists] -> 0 | Q3: =tblPlayers[expected_goal_involvements] -> 0 | R3: =IF(I3=0,0,L3/I3*90) -> 0 | S3: =IF(I3=0,0,O3/I3*90) -> 0 | T3: =IF(I3=0,0,P3/I3*90) -> 0 | U3: =IF(I3=0,0,Q3/I3*90) -> 0 | V3: =IF(E3=0,0,L3/E3) -> 0 | W3: =IF(E3=0,0,Q3/E3) -> 0 | X3: =IFERROR(IF(OR($B3="MID",$B3="FWD"),INDEX(FIXTURE_ANALYSIS!$Q:$Q,MATCH($D3,FIXTURE_ANALYSIS!$A:$A,0)),INDEX(FIXTURE_ANALYSIS!$R:$R,MATCH($D3,FIXTURE_ANALYSIS!$A:$A,0))),1) -> 1.1808552 | Y3: =X3 -> 1.1808552 | Z3: =INDEX(FPL_Raw_Data!$T:$T,MATCH(A3,FPL_Raw_Data!$AA:$AA,0)) -> 0 | AA3: =INDEX(FPL_Raw_Data!$S:$S,MATCH(A3,FPL_Raw_Data!$AA:$AA,0)) -> 0 | AB3: =IF(B3="DEF",MIN(AA3/10,1),IF(OR(B3="MID",B3="FWD"),MIN(AA3/12,1),0)) -> 0 | AC3: =INDEX(FPL_Raw_Data!$Q:$Q,MATCH(A3,FPL_Raw_Data!$AA:$AA,0)) -> 0 | AD3: =INDEX(FPL_Raw_Data!$R:$R,MATCH(A3,FPL_Raw_Data!$AA:$AA,0)) -> 0 | AE3: =INDEX(FPL_Raw_Data!$N:$N,MATCH(A3,FPL_Raw_Data!$AA:$AA,0)) -> 0 | AF3: =INDEX(FPL_Raw_Data!$L:$L,MATCH(A3,FPL_Raw_Data!$AA:$AA,0)) -> 0 | AG3: =INDEX(FPL_Raw_Data!$M:$M,MATCH(A3,FPL_Raw_Data!$AA:$AA,0)) -> 0 | AH3: =IF(B3="GK",S3*10,IF(B3="DEF",S3*6,IF(B3="MID",S3*5,S3*4))) -> 0 | AI3: =T3*3 -> 0 | AJ3: =K3*2 -> 0 | AK3: =AB3*2 -> 0 | AL3: =IFERROR(AE3/Z3,0) -> 0 | AM3: =IF(OR(B3="GK",B3="DEF"),AL3*4,IF(B3="MID",AL3*1,0)) -> 0 | AN3: =IFERROR(AC3/Z3,0) -> 0 | AO3: =IFERROR(_xlfn.PERCENTRANK.INC($R$2:$R$700,R3)*100,0) -> 0.1 | AP3: =IFERROR(_xlfn.PERCENTRANK.INC($U$2:$U$700,U3)*100,0) -> 0 | AQ3: =IFERROR(_xlfn.PERCENTRANK.INC($V$2:$V$700,V3)*100,0) -> 0.1 | AR3: =IFERROR(_xlfn.PERCENTRANK.INC($W$2:$W$700,W3)*100,0) -> 0 | AS3: =K3*100 -> 0 | AT3: =IFERROR(INDEX(Player_Model!$BC$2:$BC$596,MATCH($A3,Player_Model!$A$2:$A$596,0)),0) -> 0 | AU3: =Table8[[#This Row],[Model Expected Points]]*Table8[[#This Row],[Fixture Adjustment]] -> 0 | AV3: =Table8[[#This Row],[Fixture Adjusted Points / 90]]/Table8[[#This Row],[Price]] -> 0 | AW3: =IF(OR(B3="MID",B3="FWD"),AVERAGE(AO3,AP3),IF(B3="DEF",AP3,0)) -> 0 | AX3: =IF(B3="GK",AVERAGE(AS3,X3),IF(B3="DEF",AVERAGE(AB3,X3),IF(B3="MID",AB3,0))) -> 0.5904276 | AY3: =AS3 -> 0 | AZ3: =X3 -> 1.1808552 | BA3: =Table8[[#This Row],[Model Score2]] -> 0 | BB3: =IFERROR(INDEX(Player_Model!$BG$2:$BG$596,MATCH($A3,Player_Model!$A$2:$A$596,0)),"") -> 22 | BC3: =IF(BB3=1,"TOP PICK",IF(BB3<=5,"STRONG PICK",IF(BB3<=10,"CONSIDER","AVOID"))) -> AVOID | BD3: =IF(H3=1,Table8[[#This Row],[Model Score]],-10000) -> 0 | BE3: =IFERROR(INDEX(Player_Model!$BF$2:$BF$596,MATCH($A3,Player_Model!$A$2:$A$596,0)),"") -> 253 | BF3: =IFERROR(INDEX(Player_Model!$BG$2:$BG$596,MATCH($A3,Player_Model!$A$2:$A$596,0)),"") -> 22 | BG3: =IFERROR(INDEX(Player_Model!$BE$2:$BE$596,MATCH($A3,Player_Model!$A$2:$A$596,0)),0) -> 0
A4: =tblPlayers[first_name]&" "&tblPlayers[second_name] -> Illan Meslier | B4: =_xlfn.SWITCH(tblPlayers[element_type],1,"GK",2,"DEF",3,"MID",4,"FWD") -> GK | C4: =tblPlayers[team] -> 1 | D4: =INDEX(tblTeams[Column1.short_name],MATCH(C4,tblTeams[Column1.id],0)) -> ARS | E4: =INDEX(FPL_Raw_Data!$F:$F,MATCH(A4,FPL_Raw_Data!$AA:$AA,0))/10 -> 4.9 | F4: =tblPlayers[[#This Row],[status]] -> a | G4: =tblPlayers[[#This Row],[can_select]] -> TRUE | H4: =IF(AND(Table8[[#This Row],[Availability Status]]="a",Table8[[#This Row],[Can Select]]=TRUE),1,0) -> 1 | I4: =tblPlayers[minutes] -> 0 | J4: =Table8[[#This Row],[Minutes]]/90 -> 0 | K4: =IFERROR(Z4/(FIXTURE_ANALYSIS!$B$1-1),0) -> 0 | L4: =tblPlayers[total_points] -> 0 | M4: =tblPlayers[points_per_game] -> 0 | N4: =tblPlayers[form] -> 0 | O4: =tblPlayers[expected_goals] -> 0 | P4: =tblPlayers[expected_assists] -> 0 | Q4: =tblPlayers[expected_goal_involvements] -> 0 | R4: =IF(I4=0,0,L4/I4*90) -> 0 | S4: =IF(I4=0,0,O4/I4*90) -> 0 | T4: =IF(I4=0,0,P4/I4*90) -> 0 | U4: =IF(I4=0,0,Q4/I4*90) -> 0 | V4: =IF(E4=0,0,L4/E4) -> 0 | W4: =IF(E4=0,0,Q4/E4) -> 0 | X4: =IFERROR(IF(OR($B4="MID",$B4="FWD"),INDEX(FIXTURE_ANALYSIS!$Q:$Q,MATCH($D4,FIXTURE_ANALYSIS!$A:$A,0)),INDEX(FIXTURE_ANALYSIS!$R:$R,MATCH($D4,FIXTURE_ANALYSIS!$A:$A,0))),1) -> 1.1808552 | Y4: =X4 -> 1.1808552 | Z4: =INDEX(FPL_Raw_Data!$T:$T,MATCH(A4,FPL_Raw_Data!$AA:$AA,0)) -> 0 | AA4: =INDEX(FPL_Raw_Data!$S:$S,MATCH(A4,FPL_Raw_Data!$AA:$AA,0)) -> 0 | AB4: =IF(B4="DEF",MIN(AA4/10,1),IF(OR(B4="MID",B4="FWD"),MIN(AA4/12,1),0)) -> 0 | AC4: =INDEX(FPL_Raw_Data!$Q:$Q,MATCH(A4,FPL_Raw_Data!$AA:$AA,0)) -> 0 | AD4: =INDEX(FPL_Raw_Data!$R:$R,MATCH(A4,FPL_Raw_Data!$AA:$AA,0)) -> 0 | AE4: =INDEX(FPL_Raw_Data!$N:$N,MATCH(A4,FPL_Raw_Data!$AA:$AA,0)) -> 0 | AF4: =INDEX(FPL_Raw_Data!$L:$L,MATCH(A4,FPL_Raw_Data!$AA:$AA,0)) -> 0 | AG4: =INDEX(FPL_Raw_Data!$M:$M,MATCH(A4,FPL_Raw_Data!$AA:$AA,0)) -> 0 | AH4: =IF(B4="GK",S4*10,IF(B4="DEF",S4*6,IF(B4="MID",S4*5,S4*4))) -> 0 | AI4: =T4*3 -> 0 | AJ4: =K4*2 -> 0 | AK4: =AB4*2 -> 0 | AL4: =IFERROR(AE4/Z4,0) -> 0 | AM4: =IF(OR(B4="GK",B4="DEF"),AL4*4,IF(B4="MID",AL4*1,0)) -> 0 | AN4: =IFERROR(AC4/Z4,0) -> 0 | AO4: =IFERROR(_xlfn.PERCENTRANK.INC($R$2:$R$700,R4)*100,0) -> 0.1 | AP4: =IFERROR(_xlfn.PERCENTRANK.INC($U$2:$U$700,U4)*100,0) -> 0 | AQ4: =IFERROR(_xlfn.PERCENTRANK.INC($V$2:$V$700,V4)*100,0) -> 0.1 | AR4: =IFERROR(_xlfn.PERCENTRANK.INC($W$2:$W$700,W4)*100,0) -> 0 | AS4: =K4*100 -> 0 | AT4: =IFERROR(INDEX(Player_Model!$BC$2:$BC$596,MATCH($A4,Player_Model!$A$2:$A$596,0)),0) -> 0 | AU4: =Table8[[#This Row],[Model Expected Points]]*Table8[[#This Row],[Fixture Adjustment]] -> 0 | AV4: =Table8[[#This Row],[Fixture Adjusted Points / 90]]/Table8[[#This Row],[Price]] -> 0 | AW4: =IF(OR(B4="MID",B4="FWD"),AVERAGE(AO4,AP4),IF(B4="DEF",AP4,0)) -> 0 | AX4: =IF(B4="GK",AVERAGE(AS4,X4),IF(B4="DEF",AVERAGE(AB4,X4),IF(B4="MID",AB4,0))) -> 0.5904276 | AY4: =AS4 -> 0 | AZ4: =X4 -> 1.1808552 | BA4: =Table8[[#This Row],[Model Score2]] -> 0 | BB4: =IFERROR(INDEX(Player_Model!$BG$2:$BG$596,MATCH($A4,Player_Model!$A$2:$A$596,0)),"") -> 23 | BC4: =IF(BB4=1,"TOP PICK",IF(BB4<=5,"STRONG PICK",IF(BB4<=10,"CONSIDER","AVOID"))) -> AVOID | BD4: =IF(H4=1,Table8[[#This Row],[Model Score]],-10000) -> 0 | BE4: =IFERROR(INDEX(Player_Model!$BF$2:$BF$596,MATCH($A4,Player_Model!$A$2:$A$596,0)),"") -> 253 | BF4: =IFERROR(INDEX(Player_Model!$BG$2:$BG$596,MATCH($A4,Player_Model!$A$2:$A$596,0)),"") -> 23 | BG4: =IFERROR(INDEX(Player_Model!$BE$2:$BE$596,MATCH($A4,Player_Model!$A$2:$A$596,0)),0) -> 0
A5: =tblPlayers[first_name]&" "&tblPlayers[second_name] -> Gabriel dos Santos Magalhães | B5: =_xlfn.SWITCH(tblPlayers[element_type],1,"GK",2,"DEF",3,"MID",4,"FWD") -> DEF | C5: =tblPlayers[team] -> 1 | D5: =INDEX(tblTeams[Column1.short_name],MATCH(C5,tblTeams[Column1.id],0)) -> ARS | E5: =INDEX(FPL_Raw_Data!$F:$F,MATCH(A5,FPL_Raw_Data!$AA:$AA,0))/10 -> 8 | F5: =tblPlayers[[#This Row],[status]] -> a | G5: =tblPlayers[[#This Row],[can_select]] -> TRUE | H5: =IF(AND(Table8[[#This Row],[Availability Status]]="a",Table8[[#This Row],[Can Select]]=TRUE),1,0) -> 1 | I5: =tblPlayers[minutes] -> 270 | J5: =Table8[[#This Row],[Minutes]]/90 -> 3 | K5: =IFERROR(Z5/(FIXTURE_ANALYSIS!$B$1-1),0) -> 1 | L5: =tblPlayers[total_points] -> 15 | M5: =tblPlayers[points_per_game] -> 5 | N5: =tblPlayers[form] -> 5 | O5: =tblPlayers[expected_goals] -> 0.49 | P5: =tblPlayers[expected_assists] -> 0.05 | Q5: =tblPlayers[expected_goal_involvements] -> 0.54 | R5: =IF(I5=0,0,L5/I5*90) -> 5 | S5: =IF(I5=0,0,O5/I5*90) -> 0.16333333 | T5: =IF(I5=0,0,P5/I5*90) -> 0.016666667 | U5: =IF(I5=0,0,Q5/I5*90) -> 0.18 | V5: =IF(E5=0,0,L5/E5) -> 1.875 | W5: =IF(E5=0,0,Q5/E5) -> 0.0675 | X5: =IFERROR(IF(OR($B5="MID",$B5="FWD"),INDEX(FIXTURE_ANALYSIS!$Q:$Q,MATCH($D5,FIXTURE_ANALYSIS!$A:$A,0)),INDEX(FIXTURE_ANALYSIS!$R:$R,MATCH($D5,FIXTURE_ANALYSIS!$A:$A,0))),1) -> 1.1808552 | Y5: =X5 -> 1.1808552 | Z5: =INDEX(FPL_Raw_Data!$T:$T,MATCH(A5,FPL_Raw_Data!$AA:$AA,0)) -> 3 | AA5: =INDEX(FPL_Raw_Data!$S:$S,MATCH(A5,FPL_Raw_Data!$AA:$AA,0)) -> 21 | AB5: =IF(B5="DEF",MIN(AA5/10,1),IF(OR(B5="MID",B5="FWD"),MIN(AA5/12,1),0)) -> 1 | AC5: =INDEX(FPL_Raw_Data!$Q:$Q,MATCH(A5,FPL_Raw_Data!$AA:$AA,0)) -> 0 | AD5: =INDEX(FPL_Raw_Data!$R:$R,MATCH(A5,FPL_Raw_Data!$AA:$AA,0)) -> 54 | AE5: =INDEX(FPL_Raw_Data!$N:$N,MATCH(A5,FPL_Raw_Data!$AA:$AA,0)) -> 2 | AF5: =INDEX(FPL_Raw_Data!$L:$L,MATCH(A5,FPL_Raw_Data!$AA:$AA,0)) -> 0 | AG5: =INDEX(FPL_Raw_Data!$M:$M,MATCH(A5,FPL_Raw_Data!$AA:$AA,0)) -> 0 | AH5: =IF(B5="GK",S5*10,IF(B5="DEF",S5*6,IF(B5="MID",S5*5,S5*4))) -> 0.98 | AI5: =T5*3 -> 0.05 | AJ5: =K5*2 -> 2 | AK5: =AB5*2 -> 2 | AL5: =IFERROR(AE5/Z5,0) -> 0.66666667 | AM5: =IF(OR(B5="GK",B5="DEF"),AL5*4,IF(B5="MID",AL5*1,0)) -> 2.6666667 | AN5: =IFERROR(AC5/Z5,0) -> 0 | AO5: =IFERROR(_xlfn.PERCENTRANK.INC($R$2:$R$700,R5)*100,0) -> 75.4 | AP5: =IFERROR(_xlfn.PERCENTRANK.INC($U$2:$U$700,U5)*100,0) -> 74.7 | AQ5: =IFERROR(_xlfn.PERCENTRANK.INC($V$2:$V$700,V5)*100,0) -> 85.3 | AR5: =IFERROR(_xlfn.PERCENTRANK.INC($W$2:$W$700,W5)*100,0) -> 79.6 | AS5: =K5*100 -> 100 | AT5: =IFERROR(INDEX(Player_Model!$BC$2:$BC$596,MATCH($A5,Player_Model!$A$2:$A$596,0)),0) -> 8.1528293 | AU5: =Table8[[#This Row],[Model Expected Points]]*Table8[[#This Row],[Fixture Adjustment]] -> 9.6273109 | AV5: =Table8[[#This Row],[Fixture Adjusted Points / 90]]/Table8[[#This Row],[Price]] -> 1.2034139 | AW5: =IF(OR(B5="MID",B5="FWD"),AVERAGE(AO5,AP5),IF(B5="DEF",AP5,0)) -> 74.7 | AX5: =IF(B5="GK",AVERAGE(AS5,X5),IF(B5="DEF",AVERAGE(AB5,X5),IF(B5="MID",AB5,0))) -> 1.0904276 | AY5: =AS5 -> 100 | AZ5: =X5 -> 1.1808552 | BA5: =Table8[[#This Row],[Model Score2]] -> 8.1528293 | BB5: =IFERROR(INDEX(Player_Model!$BG$2:$BG$596,MATCH($A5,Player_Model!$A$2:$A$596,0)),"") -> 6 | BC5: =IF(BB5=1,"TOP PICK",IF(BB5<=5,"STRONG PICK",IF(BB5<=10,"CONSIDER","AVOID"))) -> CONSIDER | BD5: =IF(H5=1,Table8[[#This Row],[Model Score]],-10000) -> 8.1528293 | BE5: =IFERROR(INDEX(Player_Model!$BF$2:$BF$596,MATCH($A5,Player_Model!$A$2:$A$596,0)),"") -> 7 | BF5: =IFERROR(INDEX(Player_Model!$BG$2:$BG$596,MATCH($A5,Player_Model!$A$2:$A$596,0)),"") -> 6 | BG5: =IFERROR(INDEX(Player_Model!$BE$2:$BE$596,MATCH($A5,Player_Model!$A$2:$A$596,0)),0) -> 8.1528293
A6: =tblPlayers[first_name]&" "&tblPlayers[second_name] -> Jurriën Timber | B6: =_xlfn.SWITCH(tblPlayers[element_type],1,"GK",2,"DEF",3,"MID",4,"FWD") -> DEF | C6: =tblPlayers[team] -> 1 | D6: =INDEX(tblTeams[Column1.short_name],MATCH(C6,tblTeams[Column1.id],0)) -> ARS | E6: =INDEX(FPL_Raw_Data!$F:$F,MATCH(A6,FPL_Raw_Data!$AA:$AA,0))/10 -> 6.5 | F6: =tblPlayers[[#This Row],[status]] -> d | G6: =tblPlayers[[#This Row],[can_select]] -> TRUE | H6: =IF(AND(Table8[[#This Row],[Availability Status]]="a",Table8[[#This Row],[Can Select]]=TRUE),1,0) -> 0 | I6: =tblPlayers[minutes] -> 0 | J6: =Table8[[#This Row],[Minutes]]/90 -> 0 | K6: =IFERROR(Z6/(FIXTURE_ANALYSIS!$B$1-1),0) -> 0 | L6: =tblPlayers[total_points] -> 0 | M6: =tblPlayers[points_per_game] -> 0 | N6: =tblPlayers[form] -> 0 | O6: =tblPlayers[expected_goals] -> 0 | P6: =tblPlayers[expected_assists] -> 0 | Q6: =tblPlayers[expected_goal_involvements] -> 0 | R6: =IF(I6=0,0,L6/I6*90) -> 0 | S6: =IF(I6=0,0,O6/I6*90) -> 0 | T6: =IF(I6=0,0,P6/I6*90) -> 0 | U6: =IF(I6=0,0,Q6/I6*90) -> 0 | V6: =IF(E6=0,0,L6/E6) -> 0 | W6: =IF(E6=0,0,Q6/E6) -> 0 | X6: =IFERROR(IF(OR($B6="MID",$B6="FWD"),INDEX(FIXTURE_ANALYSIS!$Q:$Q,MATCH($D6,FIXTURE_ANALYSIS!$A:$A,0)),INDEX(FIXTURE_ANALYSIS!$R:$R,MATCH($D6,FIXTURE_ANALYSIS!$A:$A,0))),1) -> 1.1808552 | Y6: =X6 -> 1.1808552 | Z6: =INDEX(FPL_Raw_Data!$T:$T,MATCH(A6,FPL_Raw_Data!$AA:$AA,0)) -> 0 | AA6: =INDEX(FPL_Raw_Data!$S:$S,MATCH(A6,FPL_Raw_Data!$AA:$AA,0)) -> 0 | AB6: =IF(B6="DEF",MIN(AA6/10,1),IF(OR(B6="MID",B6="FWD"),MIN(AA6/12,1),0)) -> 0 | AC6: =INDEX(FPL_Raw_Data!$Q:$Q,MATCH(A6,FPL_Raw_Data!$AA:$AA,0)) -> 0 | AD6: =INDEX(FPL_Raw_Data!$R:$R,MATCH(A6,FPL_Raw_Data!$AA:$AA,0)) -> 0 | AE6: =INDEX(FPL_Raw_Data!$N:$N,MATCH(A6,FPL_Raw_Data!$AA:$AA,0)) -> 0 | AF6: =INDEX(FPL_Raw_Data!$L:$L,MATCH(A6,FPL_Raw_Data!$AA:$AA,0)) -> 0 | AG6: =INDEX(FPL_Raw_Data!$M:$M,MATCH(A6,FPL_Raw_Data!$AA:$AA,0)) -> 0 | AH6: =IF(B6="GK",S6*10,IF(B6="DEF",S6*6,IF(B6="MID",S6*5,S6*4))) -> 0 | AI6: =T6*3 -> 0 | AJ6: =K6*2 -> 0 | AK6: =AB6*2 -> 0 | AL6: =IFERROR(AE6/Z6,0) -> 0 | AM6: =IF(OR(B6="GK",B6="DEF"),AL6*4,IF(B6="MID",AL6*1,0)) -> 0 | AN6: =IFERROR(AC6/Z6,0) -> 0 | AO6: =IFERROR(_xlfn.PERCENTRANK.INC($R$2:$R$700,R6)*100,0) -> 0.1 | AP6: =IFERROR(_xlfn.PERCENTRANK.INC($U$2:$U$700,U6)*100,0) -> 0 | AQ6: =IFERROR(_xlfn.PERCENTRANK.INC($V$2:$V$700,V6)*100,0) -> 0.1 | AR6: =IFERROR(_xlfn.PERCENTRANK.INC($W$2:$W$700,W6)*100,0) -> 0 | AS6: =K6*100 -> 0 | AT6: =IFERROR(INDEX(Player_Model!$BC$2:$BC$596,MATCH($A6,Player_Model!$A$2:$A$596,0)),0) -> -0.1968092 | AU6: =Table8[[#This Row],[Model Expected Points]]*Table8[[#This Row],[Fixture Adjustment]] -> -0.23240317 | AV6: =Table8[[#This Row],[Fixture Adjusted Points / 90]]/Table8[[#This Row],[Price]] -> -0.035754333 | AW6: =IF(OR(B6="MID",B6="FWD"),AVERAGE(AO6,AP6),IF(B6="DEF",AP6,0)) -> 0 | AX6: =IF(B6="GK",AVERAGE(AS6,X6),IF(B6="DEF",AVERAGE(AB6,X6),IF(B6="MID",AB6,0))) -> 0.5904276 | AY6: =AS6 -> 0 | AZ6: =X6 -> 1.1808552 | BA6: =Table8[[#This Row],[Model Score2]] -> -0.1968092 | BB6: =IFERROR(INDEX(Player_Model!$BG$2:$BG$596,MATCH($A6,Player_Model!$A$2:$A$596,0)),"") -> 105 | BC6: =IF(BB6=1,"TOP PICK",IF(BB6<=5,"STRONG PICK",IF(BB6<=10,"CONSIDER","AVOID"))) -> AVOID | BD6: =IF(H6=1,Table8[[#This Row],[Model Score]],-10000) -> -10000 | BE6: =IFERROR(INDEX(Player_Model!$BF$2:$BF$596,MATCH($A6,Player_Model!$A$2:$A$596,0)),"") -> 508 | BF6: =IFERROR(INDEX(Player_Model!$BG$2:$BG$596,MATCH($A6,Player_Model!$A$2:$A$596,0)),"") -> 105 | BG6: =IFERROR(INDEX(Player_Model!$BE$2:$BE$596,MATCH($A6,Player_Model!$A$2:$A$596,0)),0) -> -0.1968092
